# 异常
捕捉并处理知道如何处理的异常，而抛出不知道如何处理的异常。
[TOC]
## 异常框架
![异常框架](http://www.liuhaihua.cn/wp-content/uploads/2019/03/aiMRNbA.png)

### 异常和错误
- `Exception`（异常）是应用程序中可能的可预测、可恢复问题。一般大多数异常表示中度到轻度的问题。
- `Error`（错误）表示运行应用程序中较严重问题。大多数错误与代码编写者执行的操作无关，而表示代码运行时 JVM（Java 虚拟机）出现的问题。

*`Error`一般是指java虚拟机相关的问题，如系统崩溃、虚拟机出错误、动态链接失败等，这种错误无法恢复或不可能捕获，将导致应用程序中断，通常应用程序无法处理这些错误，因此应用程序不应该捕获Error对象，也无须在其throws子句中声明该方法抛出任何Error或其子类。*

### 运行时异常和非运行异常

#### 非运行时异常（checked exception），
- 通常是从一个可以恢复的程序中抛出来的，并且最好能够从这种异常中使用程序恢复。比如FileNotFoundException。  
- 必须要对其进行处理，否则无法通过编译。  
处理方式有两种:  
1.使用try..catch..finally进行捕获；  
2.在产生异常的方法声明后面写上throws 某一个Exception类型，如throws Exception，将异常抛出到外面一层去。  



#### 运行时异常（unchecked exception）
- 出现运行时异常后，如果没有捕获处理这个异常（即没有catch），系统会把异常一直往上层抛，一直到最上层，如果是多线程就由Thread.run()抛出，如果是单线程就被main()抛出。抛出之后，如果是线程，这个线程也就退出了。如果是主程序抛出的异常，那么这整个程序也就退出了。也就是说，你如果不对运行时异常进行处理，那么出现运行时异常之后，要么是线程中止，要么是主程序终止。 

- 从语言本身的角度讲，程序不该去catch这类异常，虽然能够从诸如RuntimeException这样的异常中catch并恢复，但是并不鼓励终端程序员这么做，因为完全没要必要。因为这类错误本身就是bug，应该被修复，出现此类错误时程序就应该立即停止执行。




## 异常处理


### 抛出异常
一个try后面可以跟多个catch，但不管多少个，最多只会有一个catch块被执行。
#### throws抛出异常
如果一个方法可能会出现异常，但没有能力处理这种异常，可以在方法声明处用throws子句来声明抛出异常。  
- 语法格式：
```java 
methodname throws Exception1,Exception2,..,ExceptionN  {  } 
```
- 规则
  1. 如果是不可查异常（unchecked exception），即Error、RuntimeException或它们的子类，那么可以不使用throws关键字来声明要抛出的异常，编译仍能顺利通过，但在运行时会被系统抛出。  
  2. 如果一个方法可能出现可查异常（checked exception），要么用try-catch语句捕获，要么用throws子句声明将它抛出，否则会导致编译错误。
  3. 只有当抛出了异常时，该方法的调用者才必须处理或者重新抛出该异常。当方法的调用者无力处理该异常的时候，应该继续抛出。
  4. 调用方法必须遵循任何可查异常的处理和声明规则。若覆盖一个方法，则不能声明与覆盖方法不同的异常。声明的任何异常必须是被覆盖方法所声明异常的同类或子类。

#### throw抛出异常
throw总是出现在方法体中，用来抛出一个Throwable类型的异常。程序会在throw语句后立即终止，它后面的语句执行不到，然后在包含它的所有try块中（可能在上层调用函数中）从里向外寻找含有与其匹配的catch子句的try块。

#### 为什么有throws和throw
- 如果**抛出了可查异常**，则还应该在方法头部声明方法可能抛出的异常类型。该方法的调用者也必须检查处理抛出的异常。假设方法抛出异常却没有声明该方法将抛出异常，那么客户程序员可以调用这个方法而且不用编写处理异常的代码。那么，一旦出现异常，那么这个异常就没有合适的异常控制器来解决。


- **覆盖父类某方法的子类方法**不能抛出比父类方法更多的异常，所以，有时设计父类的方法时会声明抛出异常，但实际的实现方法的代码却并不抛出异常，这样做的目的就是为了方便子类方法覆盖父类方法时可以抛出异常。



### 捕获异常
当一个方法出现错误引发异常时，方法创建异常对象并交付运行时系统，异常对象中包含了异常类型和异常出现时的程序状态等异常信息。运行时系统负责寻找处置异常的代码并执行。

#### try-catch语句
- 语法：  
```java
try {  
	// 可能会发生异常的程序代码  
} catch (Type1 id1){  
	// 捕获并处置try抛出的异常类型Type1  
} catch (Type2 id2){  
	 //捕获并处置try抛出的异常类型Type2  
}
```
- 匹配的原则是：如果抛出的异常对象属于catch子句的异常类，或者属于该异常类的子类，则认为生成的异常对象与catch块捕获的异常类型相匹配。

- 注意：
  1. 一旦某个catch捕获到匹配的异常类型，将进入异常处理代码。一经处理结束，就意味着整个try-catch语句结束。**其他的catch子句不再有匹配和捕获异常类型的机会**。

  2. Java通过异常类描述异常类型，对于有多个catch子句的异常程序而言，**应该尽量将捕获底层异常类的catch子句放在前面**，同时尽量将捕获相对高层的异常类的catch子句放在后面。否则，捕获底层异常类的catch子句将可能会被屏蔽。

*例如：RuntimeException异常类包括运行时各种常见的异常，ArithmeticException类和ArrayIndexOutOfBoundsException类都是它的子类。因此，RuntimeException异常类的catch子句应该放在 最后面，否则可能会屏蔽其后的特定异常处理或引起编译错误。*


#### try-catch-finally语句
- 语法：  
```java
try {  
	// 可能会发生异常的程序代码  
} catch (Type1 id1){  
	// 捕获并处置try抛出的异常类型Type1  
} catch (Type2 id2){  
	 //捕获并处置try抛出的异常类型Type2  
}finally {  
	// 无论是否发生异常，都将执行的语句块  
} 
```
- 注意：  
1. try 块：用于捕获异常。其后可接零个或多个catch块，**如果没有catch块，则必须跟一个finally块**。  
2. 在try-catch-finally中，finally语句总是会被执行，即使在try中有了return。
3. Java 异常处理中 finally 中的 return 会覆盖 catch 代码块中的 return 语句和 throw 语句，所以 Java 不建议在 finally 中使用 return 语句 。
此外 finally 中的 throw 语句也会覆盖 catch 代码块中的 return 语句和 throw 语句。

#### 自定义异常
自定义一个异常类，只需要继承`Exception`或`RuntimeException`即可。
```java
//自定义异常
class MyException extends Exception
{
	//构造方法里传递msg
	public MyException(String msg)
	{
		super(msg);
		System.err.println("MyException");
	}
}

public class ThinkingInJavaExceptionEx1
{
	public static void f() throws MyException
	{
		throw new MyException("e1");
	}
	
	public static void main (String[] args) 
	{
	//MyException e1 =new MyException("mye1");
	//怎么throw   1.try里 throw跟异常对象  2.方法名跟throws 异常类
	try{
		 f();
	}
	catch (MyException e){
		System.out.println("catch MyException");
	}
	finally {
		System.out.println("this is finally block");
	}
	}
}
```
#### 异常链
异常链是以一个异常对象为参数构造新的异常对象，新的异常对象将包含先前异常的信息。  
我们有两种方式处理异常，一是 throws 抛出交给上级处理，二是 try…catch 做具体处理。try…catch 的 catch 块我们可以不需要做任何处理，仅仅只用 throw 这个关键字将我们封装异常信息主动抛出来。然后在通过关键字 throws 继续抛出该方法异常。它的上层也可以做这样的处理，以此类推就会产生一条由异常构成的异常链。  
在Throwable的子类中，只有三种基本的异常提供了带cause参数的构造器：Error、Exception和RuntimeException。如果要把其他类型的异常链接起来，应该使用initCause()方法而非构造器。
```java
    //见Java编程思想p260
	public Object setField(String id, Object value) throws DynamicFieldsException {
		if (value == null) {
			// Most exceptions don't have a "cause" constructor.
			// In these cases you must use initCause(),
			// available in all Throwable subclasses.
			DynamicFieldsException dfe = new DynamicFieldsException();
			dfe.initCause(new NullPointerException());
			throw dfe;
		}
		int fieldNumber = hasField(id);
		if (fieldNumber == -1)
			fieldNumber = makeField(id);
		Object result = null;
		try {
			result = getField(id); // Get old value
		} catch (NoSuchFieldException e) {
			// Use constructor that takes "cause":
			throw new RuntimeException(e);
		}
		fields[fieldNumber][1] = value;
		return result;
	}
```
